<?xml version="1.0" ?>
<!-- =================================================================================== -->
<!-- |    This document was autogenerated by xacro from /home/matteo/salva_ws/src/proj_robotica/two_arms_description/urdf/array.urdf.xacro | -->
<!-- |    EDITING THIS FILE BY HAND IS NOT RECOMMENDED                                 | -->
<!-- =================================================================================== -->
<robot name="arm_pair" xmlns:xacro="http://wiki.ros.org/xacro">
    <gazebo>
        <plugin filename="libgazebo_ros_control.so" name="ros_control">
            <!--robotNamespace>/</robotNamespace-->
            <!--robotSimType>gazebo_ros_control/DefaultRobotHWSim</robotSimType-->
        </plugin>
        <!--
    <plugin name="gazebo_ros_power_monitor_controller" filename="libgazebo_ros_power_monitor.so">
      <alwaysOn>true</alwaysOn>
      <updateRate>1.0</updateRate>
      <timeout>5</timeout>
      <powerStateTopic>power_state</powerStateTopic>
      <powerStateRate>10.0</powerStateRate>
      <fullChargeCapacity>87.78</fullChargeCapacity>     
      <dischargeRate>-474</dischargeRate>
      <chargeRate>525</chargeRate>
      <dischargeVoltage>15.52</dischargeVoltage>
      <chargeVoltage>16.41</chargeVoltage>
    </plugin>
-->
    </gazebo>
    <link name="world" />
    <link name="array_box">
        <inertial>
            <origin rpy="0 0 0" xyz="0 0 0.0125" />
            <mass value="1000" />
        </inertial>
        <visual>
            <origin rpy="0 0 0" xyz="0 0 0.0125" />
            <geometry>
                <box size="0.7 0.25 0.025" />
            </geometry>
            <material name="Gray">
                <color rgba="0.7 0.7 0.7 1" />
            </material>
        </visual>
        <collision>
            <origin rpy="0 0 0" xyz="0 0 0.0125" />
            <geometry>
                <box size="0.7 0.25 0.025" />
            </geometry>
        </collision>
        
<inertial>
            <mass value="0.1" />
            <inertia ixx="0.03" iyy="0.03" izz="0.03" ixy="0.0" ixz="0.0" iyz="0.0" />
        </inertial>

    </link>

    <!-- measured from model -->
    <!--property name="shoulder_height" value="0.089159" /-->
    <!--property name="shoulder_offset" value="0.13585" /-->
    <!-- shoulder_offset - elbow_offset + wrist_1_length = 0.10915 -->
    <!--property name="upper_arm_length" value="0.42500" /-->
    <!--property name="elbow_offset" value="0.1197" /-->
    <!-- CAD measured -->
    <!--property name="forearm_length" value="0.39225" /-->
    <!--property name="wrist_1_length" value="0.093" /-->
    <!-- CAD measured -->
    <!--property name="wrist_2_length" value="0.09465" /-->
    <!-- In CAD this distance is 0.930, but in the spec it is 0.09465 -->
    <!--property name="wrist_3_length" value="0.0823" /-->
    <!-- manually measured -->
    <link name="rright_base_link">
        <visual>
            <geometry>
                <mesh filename="package://ur_description/meshes/ur5/visual/base.dae" />
            </geometry>
            <material name="LightGrey">
                <color rgba="0.7 0.7 0.7 1.0" />
            </material>
        </visual>
        <collision>
            <geometry>
                <mesh filename="package://ur_description/meshes/ur5/collision/base.stl" />
            </geometry>
        </collision>
        
<inertial>
            <mass value="4.0" />
            <origin rpy="0 0 0" xyz="0.0 0.0 0.0" />
            <inertia ixx="0.00443333156" ixy="0.0" ixz="0.0" iyy="0.00443333156" iyz="0.0" izz="0.0072" />
        </inertial>

    </link>
    <joint name="rright_shoulder_pan_joint" type="revolute">
        <parent link="rright_base_link" />
        <child link="rright_shoulder_link" />
        <origin rpy="0.0 0.0 0.0" xyz="0.0 0.0 0.089159" />
        <axis xyz="0 0 1" />
        <limit effort="150.0" lower="-6.28318530718" upper="6.28318530718" velocity="3.15" />
        <dynamics damping="0.0" friction="0.0" />
    </joint>
    <link name="rright_shoulder_link">
        <visual>
            <geometry>
                <mesh filename="package://ur_description/meshes/ur5/visual/shoulder.dae" />
            </geometry>
            <material name="LightGrey">
                <color rgba="0.7 0.7 0.7 1.0" />
            </material>
        </visual>
        <collision>
            <geometry>
                <mesh filename="package://ur_description/meshes/ur5/collision/shoulder.stl" />
            </geometry>
        </collision>
        
<inertial>
            <mass value="3.7" />
            <origin rpy="0 0 0" xyz="0.0 0.0 0.0" />
            <inertia ixx="0.010267495893" ixy="0.0" ixz="0.0" iyy="0.010267495893" iyz="0.0" izz="0.00666" />
        </inertial>

    </link>
    <joint name="rright_shoulder_lift_joint" type="revolute">
        <parent link="rright_shoulder_link" />
        <child link="rright_upper_arm_link" />
        <!--<origin xyz="0.0 ${shoulder_offset} 0.0" rpy="0.0 ${pi / 2.0} 0.0" />-->
        <origin rpy="0.0 0.0 0.0" xyz="0.0 0.13585 0.0" />
        <axis xyz="0 1 0" />
        <limit effort="150.0" lower="-6.28318530718" upper="6.28318530718" velocity="3.15" />
        <dynamics damping="0.0" friction="0.0" />
    </joint>
    <link name="rright_upper_arm_link">
        <visual>
            <geometry>
                <mesh filename="package://ur_description/meshes/ur5/visual/upperarm.dae" />
            </geometry>
            <material name="LightGrey">
                <color rgba="0.7 0.7 0.7 1.0" />
            </material>
        </visual>
        <collision>
            <geometry>
                <mesh filename="package://ur_description/meshes/ur5/collision/upperarm.stl" />
            </geometry>
        </collision>
        
<inertial>
            <mass value="8.393" />
            <origin rpy="0 0 0" xyz="0.0 0.0 0.28" />
            <inertia ixx="0.22689067591" ixy="0.0" ixz="0.0" iyy="0.22689067591" iyz="0.0" izz="0.0151074" />
        </inertial>

    </link>
    <joint name="rright_elbow_joint" type="revolute">
        <parent link="rright_upper_arm_link" />
        <child link="rright_forearm_link" />
        <origin rpy="0.0 0.0 0.0" xyz="0.0 -0.1197 0.425" />
        <axis xyz="0 1 0" />
        <limit effort="150.0" lower="-3.14159265359" upper="3.14159265359" velocity="3.15" />
        <dynamics damping="0.0" friction="0.0" />
    </joint>
    <link name="rright_forearm_link">
        <visual>
            <geometry>
                <mesh filename="package://ur_description/meshes/ur5/visual/forearm.dae" />
            </geometry>
            <material name="LightGrey">
                <color rgba="0.7 0.7 0.7 1.0" />
            </material>
        </visual>
        <collision>
            <geometry>
                <mesh filename="package://ur_description/meshes/ur5/collision/forearm.stl" />
            </geometry>
        </collision>
        
<inertial>
            <mass value="2.275" />
            <origin rpy="0 0 0" xyz="0.0 0.0 0.196125" />
            <inertia ixx="0.0312167910289" ixy="0.0" ixz="0.0" iyy="0.0312167910289" iyz="0.0" izz="0.004095" />
        </inertial>

    </link>
    <joint name="rright_wrist_1_joint" type="revolute">
        <parent link="rright_forearm_link" />
        <child link="rright_wrist_1_link" />
        <origin rpy="0.0 1.57079632679 0.0" xyz="0.0 0.0 0.39225" />
        <axis xyz="0 1 0" />
        <limit effort="28.0" lower="-6.28318530718" upper="6.28318530718" velocity="3.2" />
        <dynamics damping="0.0" friction="0.0" />
    </joint>
    <link name="rright_wrist_1_link">
        <visual>
            <geometry>
                <mesh filename="package://ur_description/meshes/ur5/visual/wrist1.dae" />
            </geometry>
            <material name="LightGrey">
                <color rgba="0.7 0.7 0.7 1.0" />
            </material>
        </visual>
        <collision>
            <geometry>
                <mesh filename="package://ur_description/meshes/ur5/collision/wrist1.stl" />
            </geometry>
        </collision>
        
<inertial>
            <mass value="1.219" />
            <origin rpy="0 0 0" xyz="0.0 0.093 0.0" />
            <inertia ixx="0.00255989897604" ixy="0.0" ixz="0.0" iyy="0.00255989897604" iyz="0.0" izz="0.0021942" />
        </inertial>

    </link>
    <joint name="rright_wrist_2_joint" type="revolute">
        <parent link="rright_wrist_1_link" />
        <child link="rright_wrist_2_link" />
        <origin rpy="0.0 0.0 0.0" xyz="0.0 0.093 0.0" />
        <axis xyz="0 0 1" />
        <limit effort="28.0" lower="-6.28318530718" upper="6.28318530718" velocity="3.2" />
        <dynamics damping="0.0" friction="0.0" />
    </joint>
    <link name="rright_wrist_2_link">
        <visual>
            <geometry>
                <mesh filename="package://ur_description/meshes/ur5/visual/wrist2.dae" />
            </geometry>
            <material name="LightGrey">
                <color rgba="0.7 0.7 0.7 1.0" />
            </material>
        </visual>
        <collision>
            <geometry>
                <mesh filename="package://ur_description/meshes/ur5/collision/wrist2.stl" />
            </geometry>
        </collision>
        
<inertial>
            <mass value="1.219" />
            <origin rpy="0 0 0" xyz="0.0 0.0 0.09465" />
            <inertia ixx="0.00255989897604" ixy="0.0" ixz="0.0" iyy="0.00255989897604" iyz="0.0" izz="0.0021942" />
        </inertial>

    </link>
    <joint name="rright_wrist_3_joint" type="revolute">
        <parent link="rright_wrist_2_link" />
        <child link="rright_wrist_3_link" />
        <origin rpy="0.0 0.0 0.0" xyz="0.0 0.0 0.09465" />
        <axis xyz="0 1 0" />
        <limit effort="28.0" lower="-6.28318530718" upper="6.28318530718" velocity="3.2" />
        <dynamics damping="0.0" friction="0.0" />
    </joint>
    <link name="rright_wrist_3_link">
        <visual>
            <geometry>
                <mesh filename="package://ur_description/meshes/ur5/visual/wrist3.dae" />
            </geometry>
            <material name="LightGrey">
                <color rgba="0.7 0.7 0.7 1.0" />
            </material>
        </visual>
        <collision>
            <geometry>
                <mesh filename="package://ur_description/meshes/ur5/collision/wrist3.stl" />
            </geometry>
        </collision>
        
<inertial>
            <mass value="0.1879" />
            <origin rpy="1.57079632679 0 0" xyz="0.0 0.06505 0.0" />
            <inertia ixx="8.46958911216e-05" ixy="0.0" ixz="0.0" iyy="8.46958911216e-05" iyz="0.0" izz="0.0001321171875" />
        </inertial>

    </link>
    <joint name="rright_ee_fixed_joint" type="fixed">
        <parent link="rright_wrist_3_link" />
        <child link="rright_ee_link" />
        <origin rpy="0.0 0.0 1.57079632679" xyz="0.0 0.0823 0.0" />
    </joint>
    <link name="rright_ee_link">
        <collision>
            <geometry>
                <box size="0.01 0.01 0.01" />
            </geometry>
            <origin rpy="0 0 0" xyz="-0.01 0 0" />
        </collision>
        
<inertial>
            <mass value="0.1" />
            <inertia ixx="0.03" iyy="0.03" izz="0.03" ixy="0.0" ixz="0.0" iyz="0.0" />
        </inertial>

    </link>
    <transmission name="rright_shoulder_pan_trans">
        <type>transmission_interface/SimpleTransmission</type>
        <joint name="rright_shoulder_pan_joint">
            <hardwareInterface>hardware_interface/PositionJointInterface</hardwareInterface>
        </joint>
        <actuator name="rright_shoulder_pan_motor">
            <mechanicalReduction>1</mechanicalReduction>
        </actuator>
    </transmission>
    <transmission name="rright_shoulder_lift_trans">
        <type>transmission_interface/SimpleTransmission</type>
        <joint name="rright_shoulder_lift_joint">
            <hardwareInterface>hardware_interface/PositionJointInterface</hardwareInterface>
        </joint>
        <actuator name="rright_shoulder_lift_motor">
            <mechanicalReduction>1</mechanicalReduction>
        </actuator>
    </transmission>
    <transmission name="rright_elbow_trans">
        <type>transmission_interface/SimpleTransmission</type>
        <joint name="rright_elbow_joint">
            <hardwareInterface>hardware_interface/PositionJointInterface</hardwareInterface>
        </joint>
        <actuator name="rright_elbow_motor">
            <mechanicalReduction>1</mechanicalReduction>
        </actuator>
    </transmission>
    <transmission name="rright_wrist_1_trans">
        <type>transmission_interface/SimpleTransmission</type>
        <joint name="rright_wrist_1_joint">
            <hardwareInterface>hardware_interface/PositionJointInterface</hardwareInterface>
        </joint>
        <actuator name="rright_wrist_1_motor">
            <mechanicalReduction>1</mechanicalReduction>
        </actuator>
    </transmission>
    <transmission name="rright_wrist_2_trans">
        <type>transmission_interface/SimpleTransmission</type>
        <joint name="rright_wrist_2_joint">
            <hardwareInterface>hardware_interface/PositionJointInterface</hardwareInterface>
        </joint>
        <actuator name="rright_wrist_2_motor">
            <mechanicalReduction>1</mechanicalReduction>
        </actuator>
    </transmission>
    <transmission name="rright_wrist_3_trans">
        <type>transmission_interface/SimpleTransmission</type>
        <joint name="rright_wrist_3_joint">
            <hardwareInterface>hardware_interface/PositionJointInterface</hardwareInterface>
        </joint>
        <actuator name="rright_wrist_3_motor">
            <mechanicalReduction>1</mechanicalReduction>
        </actuator>
    </transmission>
    <gazebo reference="rright_shoulder_link">
        <selfCollide>true</selfCollide>
    </gazebo>
    <gazebo reference="rright_upper_arm_link">
        <selfCollide>true</selfCollide>
    </gazebo>
    <gazebo reference="rright_forearm_link">
        <selfCollide>true</selfCollide>
    </gazebo>
    <gazebo reference="rright_wrist_1_link">
        <selfCollide>true</selfCollide>
    </gazebo>
    <gazebo reference="rright_wrist_3_link">
        <selfCollide>true</selfCollide>
    </gazebo>
    <gazebo reference="rright_wrist_2_link">
        <selfCollide>true</selfCollide>
    </gazebo>
    <gazebo reference="rright_ee_link">
        <selfCollide>true</selfCollide>
    </gazebo>
    <!-- ROS base_link to UR 'Base' Coordinates transform -->
    <link name="rright_base" />
    <joint name="rright_base_link-base_fixed_joint" type="fixed">
        <!-- NOTE: this rotation is only needed as long as base_link itself is
                 not corrected wrt the real robot (ie: rotated over 180
                 degrees)
      -->
        <origin rpy="0 0 -3.14159265359" xyz="0 0 0" />
        <parent link="rright_base_link" />
        <child link="rright_base" />
    </joint>
    <!-- Frame coincident with all-zeros TCP on UR controller -->
    <link name="rright_tool0" />
    <joint name="rright_wrist_3_link-tool0_fixed_joint" type="fixed">
        <origin rpy="-1.57079632679 0 0" xyz="0 0.0823 0" />
        <parent link="rright_wrist_3_link" />
        <child link="rright_tool0" />
    </joint>
    <!-- measured from model -->
    <!--property name="shoulder_height" value="0.089159" /-->
    <!--property name="shoulder_offset" value="0.13585" /-->
    <!-- shoulder_offset - elbow_offset + wrist_1_length = 0.10915 -->
    <!--property name="upper_arm_length" value="0.42500" /-->
    <!--property name="elbow_offset" value="0.1197" /-->
    <!-- CAD measured -->
    <!--property name="forearm_length" value="0.39225" /-->
    <!--property name="wrist_1_length" value="0.093" /-->
    <!-- CAD measured -->
    <!--property name="wrist_2_length" value="0.09465" /-->
    <!-- In CAD this distance is 0.930, but in the spec it is 0.09465 -->
    <!--property name="wrist_3_length" value="0.0823" /-->
    <!-- manually measured -->
    <link name="rleft_base_link">
        <visual>
            <geometry>
                <mesh filename="package://ur_description/meshes/ur5/visual/base.dae" />
            </geometry>
            <material name="LightGrey">
                <color rgba="0.7 0.7 0.7 1.0" />
            </material>
        </visual>
        <collision>
            <geometry>
                <mesh filename="package://ur_description/meshes/ur5/collision/base.stl" />
            </geometry>
        </collision>
        
<inertial>
            <mass value="4.0" />
            <origin rpy="0 0 0" xyz="0.0 0.0 0.0" />
            <inertia ixx="0.00443333156" ixy="0.0" ixz="0.0" iyy="0.00443333156" iyz="0.0" izz="0.0072" />
        </inertial>

    </link>
    <joint name="rleft_shoulder_pan_joint" type="revolute">
        <parent link="rleft_base_link" />
        <child link="rleft_shoulder_link" />
        <origin rpy="0.0 0.0 0.0" xyz="0.0 0.0 0.089159" />
        <axis xyz="0 0 1" />
        <limit effort="150.0" lower="-6.28318530718" upper="6.28318530718" velocity="3.15" />
        <dynamics damping="0.0" friction="0.0" />
    </joint>
    <link name="rleft_shoulder_link">
        <visual>
            <geometry>
                <mesh filename="package://ur_description/meshes/ur5/visual/shoulder.dae" />
            </geometry>
            <material name="LightGrey">
                <color rgba="0.7 0.7 0.7 1.0" />
            </material>
        </visual>
        <collision>
            <geometry>
                <mesh filename="package://ur_description/meshes/ur5/collision/shoulder.stl" />
            </geometry>
        </collision>
        
<inertial>
            <mass value="3.7" />
            <origin rpy="0 0 0" xyz="0.0 0.0 0.0" />
            <inertia ixx="0.010267495893" ixy="0.0" ixz="0.0" iyy="0.010267495893" iyz="0.0" izz="0.00666" />
        </inertial>

    </link>
    <joint name="rleft_shoulder_lift_joint" type="revolute">
        <parent link="rleft_shoulder_link" />
        <child link="rleft_upper_arm_link" />
        <!--<origin xyz="0.0 ${shoulder_offset} 0.0" rpy="0.0 ${pi / 2.0} 0.0" />-->
        <origin rpy="0.0 0.0 0.0" xyz="0.0 0.13585 0.0" />
        <axis xyz="0 1 0" />
        <limit effort="150.0" lower="-6.28318530718" upper="6.28318530718" velocity="3.15" />
        <dynamics damping="0.0" friction="0.0" />
    </joint>
    <link name="rleft_upper_arm_link">
        <visual>
            <geometry>
                <mesh filename="package://ur_description/meshes/ur5/visual/upperarm.dae" />
            </geometry>
            <material name="LightGrey">
                <color rgba="0.7 0.7 0.7 1.0" />
            </material>
        </visual>
        <collision>
            <geometry>
                <mesh filename="package://ur_description/meshes/ur5/collision/upperarm.stl" />
            </geometry>
        </collision>
        
<inertial>
            <mass value="8.393" />
            <origin rpy="0 0 0" xyz="0.0 0.0 0.28" />
            <inertia ixx="0.22689067591" ixy="0.0" ixz="0.0" iyy="0.22689067591" iyz="0.0" izz="0.0151074" />
        </inertial>

    </link>
    <joint name="rleft_elbow_joint" type="revolute">
        <parent link="rleft_upper_arm_link" />
        <child link="rleft_forearm_link" />
        <origin rpy="0.0 0.0 0.0" xyz="0.0 -0.1197 0.425" />
        <axis xyz="0 1 0" />
        <limit effort="150.0" lower="-3.14159265359" upper="3.14159265359" velocity="3.15" />
        <dynamics damping="0.0" friction="0.0" />
    </joint>
    <link name="rleft_forearm_link">
        <visual>
            <geometry>
                <mesh filename="package://ur_description/meshes/ur5/visual/forearm.dae" />
            </geometry>
            <material name="LightGrey">
                <color rgba="0.7 0.7 0.7 1.0" />
            </material>
        </visual>
        <collision>
            <geometry>
                <mesh filename="package://ur_description/meshes/ur5/collision/forearm.stl" />
            </geometry>
        </collision>
        
<inertial>
            <mass value="2.275" />
            <origin rpy="0 0 0" xyz="0.0 0.0 0.196125" />
            <inertia ixx="0.0312167910289" ixy="0.0" ixz="0.0" iyy="0.0312167910289" iyz="0.0" izz="0.004095" />
        </inertial>

    </link>
    <joint name="rleft_wrist_1_joint" type="revolute">
        <parent link="rleft_forearm_link" />
        <child link="rleft_wrist_1_link" />
        <origin rpy="0.0 1.57079632679 0.0" xyz="0.0 0.0 0.39225" />
        <axis xyz="0 1 0" />
        <limit effort="28.0" lower="-6.28318530718" upper="6.28318530718" velocity="3.2" />
        <dynamics damping="0.0" friction="0.0" />
    </joint>
    <link name="rleft_wrist_1_link">
        <visual>
            <geometry>
                <mesh filename="package://ur_description/meshes/ur5/visual/wrist1.dae" />
            </geometry>
            <material name="LightGrey">
                <color rgba="0.7 0.7 0.7 1.0" />
            </material>
        </visual>
        <collision>
            <geometry>
                <mesh filename="package://ur_description/meshes/ur5/collision/wrist1.stl" />
            </geometry>
        </collision>
        
<inertial>
            <mass value="1.219" />
            <origin rpy="0 0 0" xyz="0.0 0.093 0.0" />
            <inertia ixx="0.00255989897604" ixy="0.0" ixz="0.0" iyy="0.00255989897604" iyz="0.0" izz="0.0021942" />
        </inertial>

    </link>
    <joint name="rleft_wrist_2_joint" type="revolute">
        <parent link="rleft_wrist_1_link" />
        <child link="rleft_wrist_2_link" />
        <origin rpy="0.0 0.0 0.0" xyz="0.0 0.093 0.0" />
        <axis xyz="0 0 1" />
        <limit effort="28.0" lower="-6.28318530718" upper="6.28318530718" velocity="3.2" />
        <dynamics damping="0.0" friction="0.0" />
    </joint>
    <link name="rleft_wrist_2_link">
        <visual>
            <geometry>
                <mesh filename="package://ur_description/meshes/ur5/visual/wrist2.dae" />
            </geometry>
            <material name="LightGrey">
                <color rgba="0.7 0.7 0.7 1.0" />
            </material>
        </visual>
        <collision>
            <geometry>
                <mesh filename="package://ur_description/meshes/ur5/collision/wrist2.stl" />
            </geometry>
        </collision>
        
<inertial>
            <mass value="1.219" />
            <origin rpy="0 0 0" xyz="0.0 0.0 0.09465" />
            <inertia ixx="0.00255989897604" ixy="0.0" ixz="0.0" iyy="0.00255989897604" iyz="0.0" izz="0.0021942" />
        </inertial>

    </link>
    <joint name="rleft_wrist_3_joint" type="revolute">
        <parent link="rleft_wrist_2_link" />
        <child link="rleft_wrist_3_link" />
        <origin rpy="0.0 0.0 0.0" xyz="0.0 0.0 0.09465" />
        <axis xyz="0 1 0" />
        <limit effort="28.0" lower="-6.28318530718" upper="6.28318530718" velocity="3.2" />
        <dynamics damping="0.0" friction="0.0" />
    </joint>
    <link name="rleft_wrist_3_link">
        <visual>
            <geometry>
                <mesh filename="package://ur_description/meshes/ur5/visual/wrist3.dae" />
            </geometry>
            <material name="LightGrey">
                <color rgba="0.7 0.7 0.7 1.0" />
            </material>
        </visual>
        <collision>
            <geometry>
                <mesh filename="package://ur_description/meshes/ur5/collision/wrist3.stl" />
            </geometry>
        </collision>
        
<inertial>
            <mass value="0.1879" />
            <origin rpy="1.57079632679 0 0" xyz="0.0 0.06505 0.0" />
            <inertia ixx="8.46958911216e-05" ixy="0.0" ixz="0.0" iyy="8.46958911216e-05" iyz="0.0" izz="0.0001321171875" />
        </inertial>

    </link>
    <joint name="rleft_ee_fixed_joint" type="fixed">
        <parent link="rleft_wrist_3_link" />
        <child link="rleft_ee_link" />
        <origin rpy="0.0 0.0 1.57079632679" xyz="0.0 0.0823 0.0" />
    </joint>
    <link name="rleft_ee_link">
        <collision>
            <geometry>
                <box size="0.01 0.01 0.01" />
            </geometry>
            <origin rpy="0 0 0" xyz="-0.01 0 0" />
        </collision>
        
<inertial>
            <mass value="0.1" />
            <inertia ixx="0.03" iyy="0.03" izz="0.03" ixy="0.0" ixz="0.0" iyz="0.0" />
        </inertial>

    </link>
    <transmission name="rleft_shoulder_pan_trans">
        <type>transmission_interface/SimpleTransmission</type>
        <joint name="rleft_shoulder_pan_joint">
            <hardwareInterface>hardware_interface/PositionJointInterface</hardwareInterface>
        </joint>
        <actuator name="rleft_shoulder_pan_motor">
            <mechanicalReduction>1</mechanicalReduction>
        </actuator>
    </transmission>
    <transmission name="rleft_shoulder_lift_trans">
        <type>transmission_interface/SimpleTransmission</type>
        <joint name="rleft_shoulder_lift_joint">
            <hardwareInterface>hardware_interface/PositionJointInterface</hardwareInterface>
        </joint>
        <actuator name="rleft_shoulder_lift_motor">
            <mechanicalReduction>1</mechanicalReduction>
        </actuator>
    </transmission>
    <transmission name="rleft_elbow_trans">
        <type>transmission_interface/SimpleTransmission</type>
        <joint name="rleft_elbow_joint">
            <hardwareInterface>hardware_interface/PositionJointInterface</hardwareInterface>
        </joint>
        <actuator name="rleft_elbow_motor">
            <mechanicalReduction>1</mechanicalReduction>
        </actuator>
    </transmission>
    <transmission name="rleft_wrist_1_trans">
        <type>transmission_interface/SimpleTransmission</type>
        <joint name="rleft_wrist_1_joint">
            <hardwareInterface>hardware_interface/PositionJointInterface</hardwareInterface>
        </joint>
        <actuator name="rleft_wrist_1_motor">
            <mechanicalReduction>1</mechanicalReduction>
        </actuator>
    </transmission>
    <transmission name="rleft_wrist_2_trans">
        <type>transmission_interface/SimpleTransmission</type>
        <joint name="rleft_wrist_2_joint">
            <hardwareInterface>hardware_interface/PositionJointInterface</hardwareInterface>
        </joint>
        <actuator name="rleft_wrist_2_motor">
            <mechanicalReduction>1</mechanicalReduction>
        </actuator>
    </transmission>
    <transmission name="rleft_wrist_3_trans">
        <type>transmission_interface/SimpleTransmission</type>
        <joint name="rleft_wrist_3_joint">
            <hardwareInterface>hardware_interface/PositionJointInterface</hardwareInterface>
        </joint>
        <actuator name="rleft_wrist_3_motor">
            <mechanicalReduction>1</mechanicalReduction>
        </actuator>
    </transmission>
    <gazebo reference="rleft_shoulder_link">
        <selfCollide>true</selfCollide>
    </gazebo>
    <gazebo reference="rleft_upper_arm_link">
        <selfCollide>true</selfCollide>
    </gazebo>
    <gazebo reference="rleft_forearm_link">
        <selfCollide>true</selfCollide>
    </gazebo>
    <gazebo reference="rleft_wrist_1_link">
        <selfCollide>true</selfCollide>
    </gazebo>
    <gazebo reference="rleft_wrist_3_link">
        <selfCollide>true</selfCollide>
    </gazebo>
    <gazebo reference="rleft_wrist_2_link">
        <selfCollide>true</selfCollide>
    </gazebo>
    <gazebo reference="rleft_ee_link">
        <selfCollide>true</selfCollide>
    </gazebo>
    <!-- ROS base_link to UR 'Base' Coordinates transform -->
    <link name="rleft_base" />
    <joint name="rleft_base_link-base_fixed_joint" type="fixed">
        <!-- NOTE: this rotation is only needed as long as base_link itself is
                 not corrected wrt the real robot (ie: rotated over 180
                 degrees)
      -->
        <origin rpy="0 0 -3.14159265359" xyz="0 0 0" />
        <parent link="rleft_base_link" />
        <child link="rleft_base" />
    </joint>
    <!-- Frame coincident with all-zeros TCP on UR controller -->
    <link name="rleft_tool0" />
    <joint name="rleft_wrist_3_link-tool0_fixed_joint" type="fixed">
        <origin rpy="-1.57079632679 0 0" xyz="0 0.0823 0" />
        <parent link="rleft_wrist_3_link" />
        <child link="rleft_tool0" />
    </joint>
    <joint name="world2array" type="fixed">
        <child link="array_box" />
        <parent link="world" />
        <origin rpy="0 0 0" xyz="0 0 0" />
    </joint>
    <joint name="array2rright" type="fixed">
        <child link="rright_base_link" />
        <parent link="array_box" />
        <origin rpy="0 0 0" xyz="0.25 0 0.025" />
    </joint>
    <joint name="array2rleft" type="fixed">
        <child link="rleft_base_link" />
        <parent link="array_box" />
        <origin rpy="0 0 0" xyz="-0.25 0 0.025" />
    </joint>
    <!--Ground
    <link name="ground_box">
	    <visual>
		    <origin xyz="0 0 0" rpy="0 0 0"/>
	 	    <geometry>
		        <box size="2 2 0.001"/> 
		    </geometry>
		    <material name="Brown">
		        <color rgba="0.7 0.7 0.7 1.0"/>
		    </material>
	    </visual>
	    <collision>
		    <origin xyz="0 0 0" rpy="0 0 0"/>
		    <geometry>
		        <box size="2 2 0.001"/> 
		    </geometry>
	    </collision>
    </link>

    <joint name="world2ground" type="fixed">
        <parent link="world" />
        <child link="ground_box" />
        <origin xyz="0 0 -0.0005" rpy="0 0 0" />
    </joint>-->
    <transmission name="trans_rright_shoulder_pan_joint">
        <type>transmission_interface/SimpleTransmission</type>
        <joint name="rright_shoulder_pan_joint">
            <hardwareInterface>hardware_interface/EffortJointInterface</hardwareInterface>
        </joint>
        <actuator name="rright_shoulder_pan_joint_motor">
            <hardwareInterface>hardware_interface/EffortJointInterface</hardwareInterface>
            <mechanicalReduction>1</mechanicalReduction>
        </actuator>
    </transmission>
    <transmission name="trans_rright_shoulder_lift_joint">
        <type>transmission_interface/SimpleTransmission</type>
        <joint name="rright_shoulder_lift_joint">
            <hardwareInterface>hardware_interface/EffortJointInterface</hardwareInterface>
        </joint>
        <actuator name="rright_shoulder_lift_joint_motor">
            <hardwareInterface>hardware_interface/EffortJointInterface</hardwareInterface>
            <mechanicalReduction>1</mechanicalReduction>
        </actuator>
    </transmission>
    <transmission name="trans_rright_elbow_joint">
        <type>transmission_interface/SimpleTransmission</type>
        <joint name="rright_elbow_joint">
            <hardwareInterface>hardware_interface/EffortJointInterface</hardwareInterface>
        </joint>
        <actuator name="rright_elbow_joint_motor">
            <hardwareInterface>hardware_interface/EffortJointInterface</hardwareInterface>
            <mechanicalReduction>1</mechanicalReduction>
        </actuator>
    </transmission>
    <transmission name="trans_rright_wrist_1_joint">
        <type>transmission_interface/SimpleTransmission</type>
        <joint name="rright_wrist_1_joint">
            <hardwareInterface>hardware_interface/EffortJointInterface</hardwareInterface>
        </joint>
        <actuator name="rright_wrist_1_joint_motor">
            <hardwareInterface>hardware_interface/EffortJointInterface</hardwareInterface>
            <mechanicalReduction>1</mechanicalReduction>
        </actuator>
    </transmission>
    <transmission name="trans_rright_wrist_2_joint">
        <type>transmission_interface/SimpleTransmission</type>
        <joint name="rright_wrist_2_joint">
            <hardwareInterface>hardware_interface/EffortJointInterface</hardwareInterface>
        </joint>
        <actuator name="rright_wrist_2_joint_motor">
            <hardwareInterface>hardware_interface/EffortJointInterface</hardwareInterface>
            <mechanicalReduction>1</mechanicalReduction>
        </actuator>
    </transmission>
    <transmission name="trans_rright_wrist_3_joint">
        <type>transmission_interface/SimpleTransmission</type>
        <joint name="rright_wrist_3_joint">
            <hardwareInterface>hardware_interface/EffortJointInterface</hardwareInterface>
        </joint>
        <actuator name="rright_wrist_3_joint_motor">
            <hardwareInterface>hardware_interface/EffortJointInterface</hardwareInterface>
            <mechanicalReduction>1</mechanicalReduction>
        </actuator>
    </transmission>
    <transmission name="trans_rleft_shoulder_pan_joint">
        <type>transmission_interface/SimpleTransmission</type>
        <joint name="rleft_shoulder_pan_joint">
            <hardwareInterface>hardware_interface/EffortJointInterface</hardwareInterface>
        </joint>
        <actuator name="rleft_shoulder_pan_joint_motor">
            <hardwareInterface>hardware_interface/EffortJointInterface</hardwareInterface>
            <mechanicalReduction>1</mechanicalReduction>
        </actuator>
    </transmission>
    <transmission name="trans_rleft_shoulder_lift_joint">
        <type>transmission_interface/SimpleTransmission</type>
        <joint name="rleft_shoulder_lift_joint">
            <hardwareInterface>hardware_interface/EffortJointInterface</hardwareInterface>
        </joint>
        <actuator name="rleft_shoulder_lift_joint_motor">
            <hardwareInterface>hardware_interface/EffortJointInterface</hardwareInterface>
            <mechanicalReduction>1</mechanicalReduction>
        </actuator>
    </transmission>
    <transmission name="trans_rleft_elbow_joint">
        <type>transmission_interface/SimpleTransmission</type>
        <joint name="rleft_elbow_joint">
            <hardwareInterface>hardware_interface/EffortJointInterface</hardwareInterface>
        </joint>
        <actuator name="rleft_elbow_joint_motor">
            <hardwareInterface>hardware_interface/EffortJointInterface</hardwareInterface>
            <mechanicalReduction>1</mechanicalReduction>
        </actuator>
    </transmission>
    <transmission name="trans_rleft_wrist_1_joint">
        <type>transmission_interface/SimpleTransmission</type>
        <joint name="rleft_wrist_1_joint">
            <hardwareInterface>hardware_interface/EffortJointInterface</hardwareInterface>
        </joint>
        <actuator name="rleft_wrist_1_joint_motor">
            <hardwareInterface>hardware_interface/EffortJointInterface</hardwareInterface>
            <mechanicalReduction>1</mechanicalReduction>
        </actuator>
    </transmission>
    <transmission name="trans_rleft_wrist_2_joint">
        <type>transmission_interface/SimpleTransmission</type>
        <joint name="rleft_wrist_2_joint">
            <hardwareInterface>hardware_interface/EffortJointInterface</hardwareInterface>
        </joint>
        <actuator name="rleft_wrist_2_joint_motor">
            <hardwareInterface>hardware_interface/EffortJointInterface</hardwareInterface>
            <mechanicalReduction>1</mechanicalReduction>
        </actuator>
    </transmission>
    <transmission name="trans_rleft_wrist_3_joint">
        <type>transmission_interface/SimpleTransmission</type>
        <joint name="rleft_wrist_3_joint">
            <hardwareInterface>hardware_interface/EffortJointInterface</hardwareInterface>
        </joint>
        <actuator name="rleft_wrist_3_joint_motor">
            <hardwareInterface>hardware_interface/EffortJointInterface</hardwareInterface>
            <mechanicalReduction>1</mechanicalReduction>
        </actuator>
    </transmission>
    <gazebo>
        <plugin name="gazebo_ros_control" filename="libgazebo_ros_control.so">
            <robotNamespace>/</robotNamespace>
        </plugin>
    </gazebo>
</robot>

<transmission name="rright_shoulder_pan_trans">
        <type>transmission_interface/SimpleTransmission</type>
        <joint name="rright_shoulder_pan_joint">
            <hardwareInterface>hardware_interface/PositionJointInterface</hardwareInterface>
        </joint>
        <actuator name="rright_shoulder_pan_motor">
            <mechanicalReduction>1</mechanicalReduction>
        </actuator>
    </transmission>
    <transmission name="rright_shoulder_lift_trans">
        <type>transmission_interface/SimpleTransmission</type>
        <joint name="rright_shoulder_lift_joint">
            <hardwareInterface>hardware_interface/PositionJointInterface</hardwareInterface>
        </joint>
        <actuator name="rright_shoulder_lift_motor">
            <mechanicalReduction>1</mechanicalReduction>
        </actuator>
    </transmission>
    <transmission name="rright_elbow_trans">
        <type>transmission_interface/SimpleTransmission</type>
        <joint name="rright_elbow_joint">
            <hardwareInterface>hardware_interface/PositionJointInterface</hardwareInterface>
        </joint>
        <actuator name="rright_elbow_motor">
            <mechanicalReduction>1</mechanicalReduction>
        </actuator>
    </transmission>
    <transmission name="rright_wrist_1_trans">
        <type>transmission_interface/SimpleTransmission</type>
        <joint name="rright_wrist_1_joint">
            <hardwareInterface>hardware_interface/PositionJointInterface</hardwareInterface>
        </joint>
        <actuator name="rright_wrist_1_motor">
            <mechanicalReduction>1</mechanicalReduction>
        </actuator>
    </transmission>
    <transmission name="rright_wrist_2_trans">
        <type>transmission_interface/SimpleTransmission</type>
        <joint name="rright_wrist_2_joint">
            <hardwareInterface>hardware_interface/PositionJointInterface</hardwareInterface>
        </joint>
        <actuator name="rright_wrist_2_motor">
            <mechanicalReduction>1</mechanicalReduction>
        </actuator>
    </transmission>
    <transmission name="rright_wrist_3_trans">
        <type>transmission_interface/SimpleTransmission</type>
        <joint name="rright_wrist_3_joint">
            <hardwareInterface>hardware_interface/PositionJointInterface</hardwareInterface>
        </joint>
        <actuator name="rright_wrist_3_motor">
            <mechanicalReduction>1</mechanicalReduction>
        </actuator>
    </transmission>
    <gazebo reference="rright_shoulder_link">
        <selfCollide>true</selfCollide>
    </gazebo>
    <gazebo reference="rright_upper_arm_link">
        <selfCollide>true</selfCollide>
    </gazebo>
    <gazebo reference="rright_forearm_link">
        <selfCollide>true</selfCollide>
    </gazebo>
    <gazebo reference="rright_wrist_1_link">
        <selfCollide>true</selfCollide>
    </gazebo>
    <gazebo reference="rright_wrist_3_link">
        <selfCollide>true</selfCollide>
    </gazebo>
    <gazebo reference="rright_wrist_2_link">
        <selfCollide>true</selfCollide>
    </gazebo>
    <gazebo reference="rright_ee_link">
        <selfCollide>true</selfCollide>
    </gazebo>
    <!-- ROS base_link to UR 'Base' Coordinates transform -->
    <link name="rright_base" />
    <joint name="rright_base_link-base_fixed_joint" type="fixed">
        <!-- NOTE: this rotation is only needed as long as base_link itself is
                 not corrected wrt the real robot (ie: rotated over 180
                 degrees)
      -->
        <origin rpy="0 0 -3.14159265359" xyz="0 0 0" />
        <parent link="rright_base_link" />
        <child link="rright_base" />
    </joint>
    <!-- Frame coincident with all-zeros TCP on UR controller -->
    <link name="rright_tool0" />
    <joint name="rright_wrist_3_link-tool0_fixed_joint" type="fixed">
        <origin rpy="-1.57079632679 0 0" xyz="0 0.0823 0" />
        <parent link="rright_wrist_3_link" />
        <child link="rright_tool0" />
    </joint>
    <!-- measured from model -->
    <!--property name="shoulder_height" value="0.089159" /-->
    <!--property name="shoulder_offset" value="0.13585" /-->
    <!-- shoulder_offset - elbow_offset + wrist_1_length = 0.10915 -->
    <!--property name="upper_arm_length" value="0.42500" /-->
    <!--property name="elbow_offset" value="0.1197" /-->
    <!-- CAD measured -->
    <!--property name="forearm_length" value="0.39225" /-->
    <!--property name="wrist_1_length" value="0.093" /-->
    <!-- CAD measured -->
    <!--property name="wrist_2_length" value="0.09465" /-->
    <!-- In CAD this distance is 0.930, but in the spec it is 0.09465 -->
    <!--property name="wrist_3_length" value="0.0823" /-->
    <!-- manually measured -->
    <link name="rleft_base_link">
        <visual>
            <geometry>
                <mesh filename="package://ur_description/meshes/ur5/visual/base.dae" />
            </geometry>
            <material name="LightGrey">
                <color rgba="0.7 0.7 0.7 1.0" />
            </material>
        </visual>
        <collision>
            <geometry>
                <mesh filename="package://ur_description/meshes/ur5/collision/base.stl" />
            </geometry>
        </collision>
        <inertial>
            <mass value="4.0" />
            <origin rpy="0 0 0" xyz="0.0 0.0 0.0" />
            <inertia ixx="0.00443333156" ixy="0.0" ixz="0.0" iyy="0.00443333156" iyz="0.0" izz="0.0072" />
        </inertial>
    </link>
    <joint name="rleft_shoulder_pan_joint" type="revolute">
        <parent link="rleft_base_link" />
        <child link="rleft_shoulder_link" />
        <origin rpy="0.0 0.0 0.0" xyz="0.0 0.0 0.089159" />
        <axis xyz="0 0 1" />
        <limit effort="150.0" lower="-6.28318530718" upper="6.28318530718" velocity="3.15" />
        <dynamics damping="0.0" friction="0.0" />
    </joint>
    <link name="rleft_shoulder_link">
        <visual>
            <geometry>
                <mesh filename="package://ur_description/meshes/ur5/visual/shoulder.dae" />
            </geometry>
            <material name="LightGrey">
                <color rgba="0.7 0.7 0.7 1.0" />
            </material>
        </visual>
        <collision>
            <geometry>
                <mesh filename="package://ur_description/meshes/ur5/collision/shoulder.stl" />
            </geometry>
        </collision>
        <inertial>
            <mass value="3.7" />
            <origin rpy="0 0 0" xyz="0.0 0.0 0.0" />
            <inertia ixx="0.010267495893" ixy="0.0" ixz="0.0" iyy="0.010267495893" iyz="0.0" izz="0.00666" />
        </inertial>
    </link>
    <joint name="rleft_shoulder_lift_joint" type="revolute">
        <parent link="rleft_shoulder_link" />
        <child link="rleft_upper_arm_link" />
        <!--<origin xyz="0.0 ${shoulder_offset} 0.0" rpy="0.0 ${pi / 2.0} 0.0" />-->
        <origin rpy="0.0 0.0 0.0" xyz="0.0 0.13585 0.0" />
        <axis xyz="0 1 0" />
        <limit effort="150.0" lower="-6.28318530718" upper="6.28318530718" velocity="3.15" />
        <dynamics damping="0.0" friction="0.0" />
    </joint>
    <link name="rleft_upper_arm_link">
        <visual>
            <geometry>
                <mesh filename="package://ur_description/meshes/ur5/visual/upperarm.dae" />
            </geometry>
            <material name="LightGrey">
                <color rgba="0.7 0.7 0.7 1.0" />
            </material>
        </visual>
        <collision>
            <geometry>
                <mesh filename="package://ur_description/meshes/ur5/collision/upperarm.stl" />
            </geometry>
        </collision>
        <inertial>
            <mass value="8.393" />
            <origin rpy="0 0 0" xyz="0.0 0.0 0.28" />
            <inertia ixx="0.22689067591" ixy="0.0" ixz="0.0" iyy="0.22689067591" iyz="0.0" izz="0.0151074" />
        </inertial>
    </link>
    <joint name="rleft_elbow_joint" type="revolute">
        <parent link="rleft_upper_arm_link" />
        <child link="rleft_forearm_link" />
        <origin rpy="0.0 0.0 0.0" xyz="0.0 -0.1197 0.425" />
        <axis xyz="0 1 0" />
        <limit effort="150.0" lower="-3.14159265359" upper="3.14159265359" velocity="3.15" />
        <dynamics damping="0.0" friction="0.0" />
    </joint>
    <link name="rleft_forearm_link">
        <visual>
            <geometry>
                <mesh filename="package://ur_description/meshes/ur5/visual/forearm.dae" />
            </geometry>
            <material name="LightGrey">
                <color rgba="0.7 0.7 0.7 1.0" />
            </material>
        </visual>
        <collision>
            <geometry>
                <mesh filename="package://ur_description/meshes/ur5/collision/forearm.stl" />
            </geometry>
        </collision>
        <inertial>
            <mass value="2.275" />
            <origin rpy="0 0 0" xyz="0.0 0.0 0.196125" />
            <inertia ixx="0.0312167910289" ixy="0.0" ixz="0.0" iyy="0.0312167910289" iyz="0.0" izz="0.004095" />
        </inertial>
    </link>
    <joint name="rleft_wrist_1_joint" type="revolute">
        <parent link="rleft_forearm_link" />
        <child link="rleft_wrist_1_link" />
        <origin rpy="0.0 1.57079632679 0.0" xyz="0.0 0.0 0.39225" />
        <axis xyz="0 1 0" />
        <limit effort="28.0" lower="-6.28318530718" upper="6.28318530718" velocity="3.2" />
        <dynamics damping="0.0" friction="0.0" />
    </joint>
    <link name="rleft_wrist_1_link">
        <visual>
            <geometry>
                <mesh filename="package://ur_description/meshes/ur5/visual/wrist1.dae" />
            </geometry>
            <material name="LightGrey">
                <color rgba="0.7 0.7 0.7 1.0" />
            </material>
        </visual>
        <collision>
            <geometry>
                <mesh filename="package://ur_description/meshes/ur5/collision/wrist1.stl" />
            </geometry>
        </collision>
        <inertial>
            <mass value="1.219" />
            <origin rpy="0 0 0" xyz="0.0 0.093 0.0" />
            <inertia ixx="0.00255989897604" ixy="0.0" ixz="0.0" iyy="0.00255989897604" iyz="0.0" izz="0.0021942" />
        </inertial>
    </link>
    <joint name="rleft_wrist_2_joint" type="revolute">
        <parent link="rleft_wrist_1_link" />
        <child link="rleft_wrist_2_link" />
        <origin rpy="0.0 0.0 0.0" xyz="0.0 0.093 0.0" />
        <axis xyz="0 0 1" />
        <limit effort="28.0" lower="-6.28318530718" upper="6.28318530718" velocity="3.2" />
        <dynamics damping="0.0" friction="0.0" />
    </joint>
    <link name="rleft_wrist_2_link">
        <visual>
            <geometry>
                <mesh filename="package://ur_description/meshes/ur5/visual/wrist2.dae" />
            </geometry>
            <material name="LightGrey">
                <color rgba="0.7 0.7 0.7 1.0" />
            </material>
        </visual>
        <collision>
            <geometry>
                <mesh filename="package://ur_description/meshes/ur5/collision/wrist2.stl" />
            </geometry>
        </collision>
        <inertial>
            <mass value="1.219" />
            <origin rpy="0 0 0" xyz="0.0 0.0 0.09465" />
            <inertia ixx="0.00255989897604" ixy="0.0" ixz="0.0" iyy="0.00255989897604" iyz="0.0" izz="0.0021942" />
        </inertial>
    </link>
    <joint name="rleft_wrist_3_joint" type="revolute">
        <parent link="rleft_wrist_2_link" />
        <child link="rleft_wrist_3_link" />
        <origin rpy="0.0 0.0 0.0" xyz="0.0 0.0 0.09465" />
        <axis xyz="0 1 0" />
        <limit effort="28.0" lower="-6.28318530718" upper="6.28318530718" velocity="3.2" />
        <dynamics damping="0.0" friction="0.0" />
    </joint>
    <link name="rleft_wrist_3_link">
        <visual>
            <geometry>
                <mesh filename="package://ur_description/meshes/ur5/visual/wrist3.dae" />
            </geometry>
            <material name="LightGrey">
                <color rgba="0.7 0.7 0.7 1.0" />
            </material>
        </visual>
        <collision>
            <geometry>
                <mesh filename="package://ur_description/meshes/ur5/collision/wrist3.stl" />
            </geometry>
        </collision>
        <inertial>
            <mass value="0.1879" />
            <origin rpy="1.57079632679 0 0" xyz="0.0 0.06505 0.0" />
            <inertia ixx="8.46958911216e-05" ixy="0.0" ixz="0.0" iyy="8.46958911216e-05" iyz="0.0" izz="0.0001321171875" />
        </inertial>
    </link>
    <joint name="rleft_ee_fixed_joint" type="fixed">
        <parent link="rleft_wrist_3_link" />
        <child link="rleft_ee_link" />
        <origin rpy="0.0 0.0 1.57079632679" xyz="0.0 0.0823 0.0" />
    </joint>
    <link name="rleft_ee_link">
        <collision>
            <geometry>
                <box size="0.01 0.01 0.01" />
            </geometry>
            <origin rpy="0 0 0" xyz="-0.01 0 0" />
        </collision>
        <inertial>
            <mass value="0.1" />
            <inertia ixx="0.03" iyy="0.03" izz="0.03" ixy="0.0" ixz="0.0" iyz="0.0" />
        </inertial>
    </link>
    <transmission name="rleft_shoulder_pan_trans">
        <type>transmission_interface/SimpleTransmission</type>
        <joint name="rleft_shoulder_pan_joint">
            <hardwareInterface>hardware_interface/PositionJointInterface</hardwareInterface>
        </joint>
        <actuator name="rleft_shoulder_pan_motor">
            <mechanicalReduction>1</mechanicalReduction>
        </actuator>
    </transmission>
    <transmission name="rleft_shoulder_lift_trans">
        <type>transmission_interface/SimpleTransmission</type>
        <joint name="rleft_shoulder_lift_joint">
            <hardwareInterface>hardware_interface/PositionJointInterface</hardwareInterface>
        </joint>
        <actuator name="rleft_shoulder_lift_motor">
            <mechanicalReduction>1</mechanicalReduction>
        </actuator>
    </transmission>
    <transmission name="rleft_elbow_trans">
        <type>transmission_interface/SimpleTransmission</type>
        <joint name="rleft_elbow_joint">
            <hardwareInterface>hardware_interface/PositionJointInterface</hardwareInterface>
        </joint>
        <actuator name="rleft_elbow_motor">
            <mechanicalReduction>1</mechanicalReduction>
        </actuator>
    </transmission>
    <transmission name="rleft_wrist_1_trans">
        <type>transmission_interface/SimpleTransmission</type>
        <joint name="rleft_wrist_1_joint">
            <hardwareInterface>hardware_interface/PositionJointInterface</hardwareInterface>
        </joint>
        <actuator name="rleft_wrist_1_motor">
            <mechanicalReduction>1</mechanicalReduction>
        </actuator>
    </transmission>
    <transmission name="rleft_wrist_2_trans">
        <type>transmission_interface/SimpleTransmission</type>
        <joint name="rleft_wrist_2_joint">
            <hardwareInterface>hardware_interface/PositionJointInterface</hardwareInterface>
        </joint>
        <actuator name="rleft_wrist_2_motor">
            <mechanicalReduction>1</mechanicalReduction>
        </actuator>
    </transmission>
    <transmission name="rleft_wrist_3_trans">
        <type>transmission_interface/SimpleTransmission</type>
        <joint name="rleft_wrist_3_joint">
            <hardwareInterface>hardware_interface/PositionJointInterface</hardwareInterface>
        </joint>
        <actuator name="rleft_wrist_3_motor">
            <mechanicalReduction>1</mechanicalReduction>
        </actuator>
    </transmission>
    <gazebo reference="rleft_shoulder_link">
        <selfCollide>true</selfCollide>
    </gazebo>
    <gazebo reference="rleft_upper_arm_link">
        <selfCollide>true</selfCollide>
    </gazebo>
    <gazebo reference="rleft_forearm_link">
        <selfCollide>true</selfCollide>
    </gazebo>
    <gazebo reference="rleft_wrist_1_link">
        <selfCollide>true</selfCollide>
    </gazebo>
    <gazebo reference="rleft_wrist_3_link">
        <selfCollide>true</selfCollide>
    </gazebo>
    <gazebo reference="rleft_wrist_2_link">
        <selfCollide>true</selfCollide>
    </gazebo>
    <gazebo reference="rleft_ee_link">
        <selfCollide>true</selfCollide>
    </gazebo>
    <!-- ROS base_link to UR 'Base' Coordinates transform -->
    <link name="rleft_base" />
    <joint name="rleft_base_link-base_fixed_joint" type="fixed">
        <!-- NOTE: this rotation is only needed as long as base_link itself is
                 not corrected wrt the real robot (ie: rotated over 180
                 degrees)
      -->
        <origin rpy="0 0 -3.14159265359" xyz="0 0 0" />
        <parent link="rleft_base_link" />
        <child link="rleft_base" />
    </joint>
    <!-- Frame coincident with all-zeros TCP on UR controller -->
    <link name="rleft_tool0" />
    <joint name="rleft_wrist_3_link-tool0_fixed_joint" type="fixed">
        <origin rpy="-1.57079632679 0 0" xyz="0 0.0823 0" />
        <parent link="rleft_wrist_3_link" />
        <child link="rleft_tool0" />
    </joint>
    <joint name="world2array" type="fixed">
        <child link="array_box" />
        <parent link="world" />
        <origin rpy="0 0 0" xyz="0 0 0" />
    </joint>
    <joint name="array2rright" type="fixed">
        <child link="rright_base_link" />
        <parent link="array_box" />
        <origin rpy="0 0 0" xyz="0.25 0 0.025" />
    </joint>
    <joint name="array2rleft" type="fixed">
        <child link="rleft_base_link" />
        <parent link="array_box" />
        <origin rpy="0 0 0" xyz="-0.25 0 0.025" />
    </joint>
    <!--Ground
    <link name="ground_box">
	    <visual>
		    <origin xyz="0 0 0" rpy="0 0 0"/>
	 	    <geometry>
		        <box size="2 2 0.001"/> 
		    </geometry>
		    <material name="Brown">
		        <color rgba="0.7 0.7 0.7 1.0"/>
		    </material>
	    </visual>
	    <collision>
		    <origin xyz="0 0 0" rpy="0 0 0"/>
		    <geometry>
		        <box size="2 2 0.001"/> 
		    </geometry>
	    </collision>
    </link>

    <joint name="world2ground" type="fixed">
        <parent link="world" />
        <child link="ground_box" />
        <origin xyz="0 0 -0.0005" rpy="0 0 0" />
    </joint>-->
    <transmission name="trans_rright_shoulder_pan_joint">
        <type>transmission_interface/SimpleTransmission</type>
        <joint name="rright_shoulder_pan_joint">
            <hardwareInterface>hardware_interface/EffortJointInterface</hardwareInterface>
        </joint>
        <actuator name="rright_shoulder_pan_joint_motor">
            <hardwareInterface>hardware_interface/EffortJointInterface</hardwareInterface>
            <mechanicalReduction>1</mechanicalReduction>
        </actuator>
    </transmission>
    <transmission name="trans_rright_shoulder_lift_joint">
        <type>transmission_interface/SimpleTransmission</type>
        <joint name="rright_shoulder_lift_joint">
            <hardwareInterface>hardware_interface/EffortJointInterface</hardwareInterface>
        </joint>
        <actuator name="rright_shoulder_lift_joint_motor">
            <hardwareInterface>hardware_interface/EffortJointInterface</hardwareInterface>
            <mechanicalReduction>1</mechanicalReduction>
        </actuator>
    </transmission>
    <transmission name="trans_rright_elbow_joint">
        <type>transmission_interface/SimpleTransmission</type>
        <joint name="rright_elbow_joint">
            <hardwareInterface>hardware_interface/EffortJointInterface</hardwareInterface>
        </joint>
        <actuator name="rright_elbow_joint_motor">
            <hardwareInterface>hardware_interface/EffortJointInterface</hardwareInterface>
            <mechanicalReduction>1</mechanicalReduction>
        </actuator>
    </transmission>
    <transmission name="trans_rright_wrist_1_joint">
        <type>transmission_interface/SimpleTransmission</type>
        <joint name="rright_wrist_1_joint">
            <hardwareInterface>hardware_interface/EffortJointInterface</hardwareInterface>
        </joint>
        <actuator name="rright_wrist_1_joint_motor">
            <hardwareInterface>hardware_interface/EffortJointInterface</hardwareInterface>
            <mechanicalReduction>1</mechanicalReduction>
        </actuator>
    </transmission>
    <transmission name="trans_rright_wrist_2_joint">
        <type>transmission_interface/SimpleTransmission</type>
        <joint name="rright_wrist_2_joint">
            <hardwareInterface>hardware_interface/EffortJointInterface</hardwareInterface>
        </joint>
        <actuator name="rright_wrist_2_joint_motor">
            <hardwareInterface>hardware_interface/EffortJointInterface</hardwareInterface>
            <mechanicalReduction>1</mechanicalReduction>
        </actuator>
    </transmission>
    <transmission name="trans_rright_wrist_3_joint">
        <type>transmission_interface/SimpleTransmission</type>
        <joint name="rright_wrist_3_joint">
            <hardwareInterface>hardware_interface/EffortJointInterface</hardwareInterface>
        </joint>
        <actuator name="rright_wrist_3_joint_motor">
            <hardwareInterface>hardware_interface/EffortJointInterface</hardwareInterface>
            <mechanicalReduction>1</mechanicalReduction>
        </actuator>
    </transmission>
    <transmission name="trans_rleft_shoulder_pan_joint">
        <type>transmission_interface/SimpleTransmission</type>
        <joint name="rleft_shoulder_pan_joint">
            <hardwareInterface>hardware_interface/EffortJointInterface</hardwareInterface>
        </joint>
        <actuator name="rleft_shoulder_pan_joint_motor">
            <hardwareInterface>hardware_interface/EffortJointInterface</hardwareInterface>
            <mechanicalReduction>1</mechanicalReduction>
        </actuator>
    </transmission>
    <transmission name="trans_rleft_shoulder_lift_joint">
        <type>transmission_interface/SimpleTransmission</type>
        <joint name="rleft_shoulder_lift_joint">
            <hardwareInterface>hardware_interface/EffortJointInterface</hardwareInterface>
        </joint>
        <actuator name="rleft_shoulder_lift_joint_motor">
            <hardwareInterface>hardware_interface/EffortJointInterface</hardwareInterface>
            <mechanicalReduction>1</mechanicalReduction>
        </actuator>
    </transmission>
    <transmission name="trans_rleft_elbow_joint">
        <type>transmission_interface/SimpleTransmission</type>
        <joint name="rleft_elbow_joint">
            <hardwareInterface>hardware_interface/EffortJointInterface</hardwareInterface>
        </joint>
        <actuator name="rleft_elbow_joint_motor">
            <hardwareInterface>hardware_interface/EffortJointInterface</hardwareInterface>
            <mechanicalReduction>1</mechanicalReduction>
        </actuator>
    </transmission>
    <transmission name="trans_rleft_wrist_1_joint">
        <type>transmission_interface/SimpleTransmission</type>
        <joint name="rleft_wrist_1_joint">
            <hardwareInterface>hardware_interface/EffortJointInterface</hardwareInterface>
        </joint>
        <actuator name="rleft_wrist_1_joint_motor">
            <hardwareInterface>hardware_interface/EffortJointInterface</hardwareInterface>
            <mechanicalReduction>1</mechanicalReduction>
        </actuator>
    </transmission>
    <transmission name="trans_rleft_wrist_2_joint">
        <type>transmission_interface/SimpleTransmission</type>
        <joint name="rleft_wrist_2_joint">
            <hardwareInterface>hardware_interface/EffortJointInterface</hardwareInterface>
        </joint>
        <actuator name="rleft_wrist_2_joint_motor">
            <hardwareInterface>hardware_interface/EffortJointInterface</hardwareInterface>
            <mechanicalReduction>1</mechanicalReduction>
        </actuator>
    </transmission>
    <transmission name="trans_rleft_wrist_3_joint">
        <type>transmission_interface/SimpleTransmission</type>
        <joint name="rleft_wrist_3_joint">
            <hardwareInterface>hardware_interface/EffortJointInterface</hardwareInterface>
        </joint>
        <actuator name="rleft_wrist_3_joint_motor">
            <hardwareInterface>hardware_interface/EffortJointInterface</hardwareInterface>
            <mechanicalReduction>1</mechanicalReduction>
        </actuator>
    </transmission>
    <gazebo>
        <plugin name="gazebo_ros_control" filename="libgazebo_ros_control.so">
            <robotNamespace>/</robotNamespace>
        </plugin>
    </gazebo>
</robot>
